<?xml version="1.0" encoding="utf-8"?>
<!-- This URDF was automatically created by SolidWorks to URDF Exporter! Originally created by Stephen Brawner (brawner@gmail.com) 
     Commit Version: 1.6.0-1-g15f4949  Build Version: 1.6.7594.29634
     For more information, please see http://wiki.ros.org/sw_urdf_exporter -->
<robot
  name="robotic_rover_v2">
  <link
    name="base_link">
    <inertial>
      <origin
        xyz="0.00288019470806633 -0.000211925177966518 -0.0766640863813122"
        rpy="0 0 0" />
      <mass
        value="3.71040926678499" />
      <inertia
        ixx="0.0167844564017488"
        ixy="-1.07692897623941E-11"
        ixz="0.00235394878307024"
        iyy="0.0337995641876472"
        iyz="-4.76502166609136E-11"
        izz="0.044705779719472" />
    </inertial>
    <visual>
      <origin
        xyz="0 0 0"
        rpy="0 0 0" />
      <geometry>
        <mesh
          filename="package://robotic_rover_v2/meshes/base_link.STL" />
      </geometry>
      <material
        name="">
        <color
          rgba="0.792156862745098 0.819607843137255 0.933333333333333 1" />
      </material>
    </visual>
    <collision>
      <origin
        xyz="0 0 0"
        rpy="0 0 0" />
      <geometry>
        <mesh
          filename="package://robotic_rover_v2/meshes/base_link.STL" />
      </geometry>
    </collision>
  </link>
  <link
    name="FL_link">
    <inertial>
      <origin
        xyz="-5.696E-06 -0.031736 -4.1427E-06"
        rpy="0 0 0" />
      <mass
        value="0.32782" />
      <inertia
        ixx="0.00076691"
        ixy="-1.0707E-07"
        ixz="8.3692E-09"
        iyy="0.0013622"
        iyz="-7.7869E-08"
        izz="0.00076691" />
    </inertial>
    <visual>
      <origin
        xyz="0 0 0"
        rpy="0 0 0" />
      <geometry>
        <mesh
          filename="package://robotic_rover_v2/meshes/FL_link.STL" />
      </geometry>
      <material
        name="">
        <color
          rgba="0.79216 0.81961 0.93333 1" />
      </material>
    </visual>
    <collision>
      <origin
        xyz="0 0 0"
        rpy="0 0 0" />
      <geometry>
        <mesh
          filename="package://robotic_rover_v2/meshes/FL_link.STL" />
      </geometry>
    </collision>
  </link>
  <joint
    name="FL_joint"
    type="continuous">
    <origin
      xyz="0.12743 0.19546 -0.255"
      rpy="0 0 0" />
    <parent
      link="base_link" />
    <child
      link="FL_link" />
    <axis
      xyz="0 1 0" />
    <limit
      effort="1"
      velocity="1" />
  </joint>
  <link
    name="FR_link">
    <inertial>
      <origin
        xyz="6.2034E-06 0.031736 -3.3353E-06"
        rpy="0 0 0" />
      <mass
        value="0.32782" />
      <inertia
        ixx="0.00076691"
        ixy="-1.1661E-07"
        ixz="-7.3383E-09"
        iyy="0.0013622"
        iyz="6.2692E-08"
        izz="0.0007669" />
    </inertial>
    <visual>
      <origin
        xyz="0 0 0"
        rpy="0 0 0" />
      <geometry>
        <mesh
          filename="package://robotic_rover_v2/meshes/FR_link.STL" />
      </geometry>
      <material
        name="">
        <color
          rgba="0.79216 0.81961 0.93333 1" />
      </material>
    </visual>
    <collision>
      <origin
        xyz="0 0 0"
        rpy="0 0 0" />
      <geometry>
        <mesh
          filename="package://robotic_rover_v2/meshes/FR_link.STL" />
      </geometry>
    </collision>
  </link>
  <joint
    name="FR_joint"
    type="continuous">
    <origin
      xyz="0.12743 -0.19654 -0.255"
      rpy="0 0 0" />
    <parent
      link="base_link" />
    <child
      link="FR_link" />
    <axis
      xyz="0 1 0" />
    <limit
      effort="1"
      velocity="1" />
  </joint>
  <link
    name="RL_link">
    <inertial>
      <origin
        xyz="-5.696E-06 -0.031736 -4.1427E-06"
        rpy="0 0 0" />
      <mass
        value="0.32782" />
      <inertia
        ixx="0.00076691"
        ixy="-1.0707E-07"
        ixz="8.3692E-09"
        iyy="0.0013622"
        iyz="-7.7869E-08"
        izz="0.00076691" />
    </inertial>
    <visual>
      <origin
        xyz="0 0 0"
        rpy="0 0 0" />
      <geometry>
        <mesh
          filename="package://robotic_rover_v2/meshes/RL_link.STL" />
      </geometry>
      <material
        name="">
        <color
          rgba="0.79216 0.81961 0.93333 1" />
      </material>
    </visual>
    <collision>
      <origin
        xyz="0 0 0"
        rpy="0 0 0" />
      <geometry>
        <mesh
          filename="package://robotic_rover_v2/meshes/RL_link.STL" />
      </geometry>
    </collision>
  </link>
  <joint
    name="RL_joint"
    type="continuous">
    <origin
      xyz="-0.12257 0.19546 -0.255"
      rpy="0 0 0" />
    <parent
      link="base_link" />
    <child
      link="RL_link" />
    <axis
      xyz="0 1 0" />
    <limit
      effort="1"
      velocity="1" />
  </joint>
  <link
    name="RR_link">
    <inertial>
      <origin
        xyz="5.69600275126744E-06 0.0317356327821493 -4.14269968324055E-06"
        rpy="0 0 0" />
      <mass
        value="0.327820252904827" />
      <inertia
        ixx="0.000766910536909882"
        ixy="-1.07067782648883E-07"
        ixz="-8.36920474953515E-09"
        iyy="0.00136217375557932"
        iyz="7.78694147343924E-08"
        izz="0.000766905116862553" />
    </inertial>
    <visual>
      <origin
        xyz="0 0 0"
        rpy="0 0 0" />
      <geometry>
        <mesh
          filename="package://robotic_rover_v2/meshes/RR_link.STL" />
      </geometry>
      <material
        name="">
        <color
          rgba="0.792156862745098 0.819607843137255 0.933333333333333 1" />
      </material>
    </visual>
    <collision>
      <origin
        xyz="0 0 0"
        rpy="0 0 0" />
      <geometry>
        <mesh
          filename="package://robotic_rover_v2/meshes/RR_link.STL" />
      </geometry>
    </collision>
  </link>
  <joint
    name="RR_joint"
    type="continuous">
    <origin
      xyz="-0.12257 -0.19654 -0.255"
      rpy="0 0 0" />
    <parent
      link="base_link" />
    <child
      link="RR_link" />
    <axis
      xyz="0 1 0" />
    <limit
      effort="1"
      velocity="1" />
  </joint>
  <link
    name="PC_link">
    <inertial>
      <origin
        xyz="2.36961184896245E-07 -3.14818393576388E-09 0.0025363637777846"
        rpy="0 0 0" />
      <mass
        value="1.36978206231541" />
      <inertia
        ixx="0.00325430497516609"
        ixy="8.99082311966181E-06"
        ixz="1.15512444398116E-07"
        iyy="0.00298770398071154"
        iyz="5.67398108801383E-09"
        izz="0.00294673225604954" />
    </inertial>
    <visual>
      <origin
        xyz="0 0 0"
        rpy="0 0 0" />
      <geometry>
        <mesh
          filename="package://robotic_rover_v2/meshes/PC_link.STL" />
      </geometry>
      <material
        name="">
        <color
          rgba="0.101960784313725 0.101960784313725 0.101960784313725 1" />
      </material>
    </visual>
    <collision>
      <origin
        xyz="0 0 0"
        rpy="0 0 0" />
      <geometry>
        <mesh
          filename="package://robotic_rover_v2/meshes/PC_link.STL" />
      </geometry>
    </collision>
  </link>
  <joint
    name="PC_joint"
    type="continuous">
    <origin
      xyz="0 0 0.27315"
      rpy="0 0 0" />
    <parent
      link="base_link" />
    <child
      link="PC_link" />
    <axis
      xyz="0 0 -1" />
    <limit
      effort="1"
      velocity="1" />
    <dynamics
      friction="0.1" />
  </joint>
  <link
    name="TC_link">
    <inertial>
      <origin
        xyz="0.000469775342715889 -0.0450102813550136 -0.00221971869479293"
        rpy="0 0 0" />
      <mass
        value="0.669748057317673" />
      <inertia
        ixx="0.000853932783644777"
        ixy="1.25962044388129E-06"
        ixz="3.31682759107268E-05"
        iyy="0.000816893642756301"
        iyz="1.13569368206194E-06"
        izz="0.000818648983044738" />
    </inertial>
    <visual>
      <origin
        xyz="0 0 0"
        rpy="0 0 0" />
      <geometry>
        <mesh
          filename="package://robotic_rover_v2/meshes/TC_link.STL" />
      </geometry>
      <material
        name="">
        <color
          rgba="0.101960784313725 0.101960784313725 0.101960784313725 1" />
      </material>
    </visual>
    <collision>
      <origin
        xyz="0 0 0"
        rpy="0 0 0" />
      <geometry>
        <mesh
          filename="package://robotic_rover_v2/meshes/TC_link.STL" />
      </geometry>
    </collision>
  </link>
  <joint
    name="TC_joint"
    type="continuous">
    <origin
      xyz="-0.001518 0.044974 0.084851"
      rpy="0 0 0" />
    <parent
      link="PC_link" />
    <child
      link="TC_link" />
    <axis
      xyz="-0.033733 0.99943 0" />
    <limit
      effort="1"
      velocity="1" />
    <dynamics
      friction="0.1" />
  </joint>

   <gazebo>
    <plugin name="skid_steer_drive_controller" filename="libgazebo_ros_skid_steer_drive.so">
      <updateRate>100.0</updateRate>
      <robotNamespace>/</robotNamespace>
      <leftFrontJoint>FL_joint</leftFrontJoint>
      <rightFrontJoint>FR_joint</rightFrontJoint>
      <leftRearJoint>RL_joint</leftRearJoint>
      <rightRearJoint>RR_joint</rightRearJoint>
      <wheelSeparation>0.3</wheelSeparation>
      <wheelDiameter>0.15</wheelDiameter>
      <robotBaseFrame>base_link</robotBaseFrame>
      <torque>20</torque>
      <commandTopic>cmd_vel</commandTopic>
      <broadcastTF>true</broadcastTF>
      <odometryTopic>odom</odometryTopic>
      <odometryFrame>odom</odometryFrame>
      <covariance_x>0.001</covariance_x> <!-- 0.0001 -->
      <covariance_y>0.001</covariance_y> <!-- 0.0001 -->
      <covariance_yaw>0.01</covariance_yaw> <!-- 0.01 -->
    </plugin>
  </gazebo>

  <!-- IMU -->

  <joint name="imu_joint" type="fixed">
    <parent link="base_link"/>
    <child link="imu_link"/>
    <origin xyz="0 0 0" rpy="0 0 0"/>
  </joint>

  <link name="imu_link"/>
  
  <gazebo reference="imu_link">
    <sensor type="imu" name="imu">
      <always_on>true</always_on>
      <visualize>true</visualize>
    </sensor>
    <material>Gazebo/FlatBlack</material>
  </gazebo>

  <gazebo>
    <plugin name="imu_plugin" filename="libgazebo_ros_imu.so">
      <alwaysOn>true</alwaysOn>
      <bodyName>imu_link</bodyName>
      <frameName>imu_link</frameName>
      <topicName>imu</topicName>
      <serviceName>imu_service</serviceName>
      <gaussianNoise>0.0</gaussianNoise>
      <updateRate>0</updateRate>
      <imu>
        <noise>
          <type>gaussian</type>
          <rate>
            <mean>0.0</mean>
            <stddev>2e-4</stddev>
            <bias_mean>0.0000075</bias_mean>
            <bias_stddev>0.0000008</bias_stddev>
          </rate>
          <accel>
            <mean>0.0</mean>
            <stddev>1.7e-2</stddev>
            <bias_mean>0.1</bias_mean>
            <bias_stddev>0.001</bias_stddev>
          </accel>
        </noise>
      </imu>
    </plugin>
  </gazebo>

  <!-- Lidar -->
  <link name="base_scan">
    <visual>
      <origin xyz="0 0 0.0" rpy="0 0 0"/>
      <geometry>
        <mesh filename="package://turtlebot3_description/meshes/sensors/lds.stl" scale="0.001 0.001 0.001"/>
      </geometry>
      <material name="dark"/>
    </visual>

    <collision>
      <origin xyz="0.015 0 -0.0065" rpy="0 0 0"/>
      <geometry>
        <cylinder length="0.0315" radius="0.055"/>
      </geometry>
    </collision>

    <inertial>
      <mass value="0.114" />
      <origin xyz="0 0 0" />
      <inertia ixx="0.001" ixy="0.0" ixz="0.0"
               iyy="0.001" iyz="0.0"
               izz="0.001" />
    </inertial>
  </link>

  <joint name="scan_joint" type="fixed">
    <parent link="base_link"/>
    <child link="base_scan"/>
    <origin xyz="-0.012 0 0.052" rpy="0 0 0"/>
  </joint>

  <gazebo reference="base_scan">
    <material>Gazebo/FlatBlack</material>
    <sensor type="ray" name="lds_lfcd_sensor">
      <pose>0 0 0 0 0 0</pose>
      <visualize>false</visualize>
      <update_rate>5</update_rate>
      <ray>
        <scan>
          <horizontal>
            <samples>360</samples>
            <resolution>1</resolution>
            <min_angle>0.0</min_angle>
            <max_angle>6.28319</max_angle>
          </horizontal>
        </scan>
        <range>
          <min>0.120</min>
          <max>3.5</max>
          <resolution>0.015</resolution>
        </range>
        <noise>
          <type>gaussian</type>
          <mean>0.0</mean>
          <stddev>0.01</stddev>
        </noise>
      </ray>
      <plugin name="gazebo_ros_lds_lfcd_controller" filename="libgazebo_ros_laser.so">
        <topicName>scan</topicName>
        <frameName>base_scan</frameName>
      </plugin>
    </sensor>
  </gazebo>


  <!-- Camera -->
  <gazebo reference="TC_link">
    <material>Gazebo/Black</material>
  </gazebo>
 <gazebo reference="PC_link">
    <material>Gazebo/Black</material>
  </gazebo>


  <!-- Wheels -->
  <gazebo reference="FL_link">
    <material>Gazebo/DarkGrey</material>
  </gazebo>
  <gazebo reference="FR_link">
    <material>Gazebo/DarkGrey</material>
  </gazebo>
  <gazebo reference="RL_link">
    <material>Gazebo/DarkGrey</material>
  </gazebo>
  <gazebo reference="RR_link">
    <material>Gazebo/DarkGrey</material>
  </gazebo>

  <!-- Main -->
  <gazebo reference="base_link">
    <material>Gazebo/White</material>
  </gazebo>

  
</robot>